<?xml version="1.0"?>
<sdf version="1.5">
  <model name="jsc_mecanum_bot">
    <static>false</static>
    <pose>0 0 0 0 0 0</pose>

    <!-- ****************** ROBOT BASE FOOTPRINT ***************************  -->
    <link name="base_footprint"/>

    <!-- ********************** ROBOT BASE *********************************  -->
    <link name="base_link">
      <inertial>
        <mass>8</mass>
        
      </inertial>
      <collision name="base_collision">
        <pose>0 0 0 0 0 0</pose> 
        <geometry>
          <box>
            <size>0.2 0.24 0.02</size>
          </box>
        </geometry>
      </collision>

      <visual name="base_visual">
        <pose>0 0 0.04 0 0 0</pose> 
        <geometry>
          <box>
            <size>0.2 0.075 0.078</size>
          </box>
        </geometry>
        <material>
          <ambient>0.5 0.7 1.0 1</ambient>
          <diffuse>0.5 0.7 1.0 1</diffuse>
          <specular>0 0 0 0</specular>
          <emissive>0 0 0 1</emissive>
        </material>
      </visual>
    </link>

    <!-- *********************** DRIVE WHEELS ******************************  -->
    <link name="fl_wheel_link">
      <pose>0.063 0.04750 0 0 0 1.570796327</pose>
      <inertial>
        <mass>0.2</mass>
        <inertia>
          <ixx>0.01</ixx> <iyy>0.01</iyy> <izz>0.01</izz>
        </inertia>
      </inertial>
      <collision name="fl_wheel_collision">
        <geometry>
          <cylinder>
            <radius>0.04</radius>
            <length>0.035</length>
          </cylinder>
        </geometry>
      </collision>

      <visual name="fl_wheel_visual">
        <geometry>
          <mesh>
            <uri>model://jsc_mecanum_bot_description/meshes/fl_wheel_link.STL</uri>
            <scale>0.5 0.5 0.5</scale>
          </mesh>
          <cylinder>
            <radius>0.04</radius>
            <length>0.035</length>
          </cylinder>
        </geometry>
        <material> 
          <ambient>0.1 0.1 0.1 1</ambient>
          <diffuse>0.1 0.1 0.1 1</diffuse>
          <specular>0 0 0 0</specular>
          <emissive>0 0 0 1</emissive>
        </material>
      </visual>
    </link>

    <link name="fr_wheel_link">
      <pose>0.063 -0.04750 0 0 0 -1.570796327</pose>
      <inertial>
        <mass>0.2</mass>
        <inertia>
          <ixx>0.01</ixx> <iyy>0.01</iyy> <izz>0.01</izz>
        </inertia>
      </inertial>
      <collision name="fr_wheel_collision">
        <geometry>
          <cylinder>
            <radius>0.04</radius>
            <length>0.035</length>
          </cylinder>
        </geometry>
      </collision>

      <visual name="fr_wheel_visual">
        <geometry>
          <mesh>
            <uri>model://jsc_mecanum_bot_description/meshes/fr_wheel_link.STL</uri>
            <scale>0.5 0.5 0.5</scale>
          </mesh>
          <cylinder>
            <radius>0.04</radius>
            <length>0.035</length>
          </cylinder>
        </geometry>
        <material> 
          <ambient>0.1 0.1 0.1 1</ambient>
          <diffuse>0.1 0.1 0.1 1</diffuse>
          <specular>0 0 0 0</specular>
          <emissive>0 0 0 1</emissive>
        </material>
      </visual>
    </link>

    <link name="rl_wheel_link">
      <pose>-0.063 0.04750 0 0 0 1.570796327</pose>
      <inertial>
        <mass>0.2</mass>
        <inertia>
          <ixx>0.01</ixx> <iyy>0.01</iyy> <izz>0.01</izz>
        </inertia>
      </inertial>
      <collision name="rl_wheel_collision">
        <geometry>
          <cylinder>
            <radius>0.04</radius>
            <length>0.035</length>
          </cylinder>
        </geometry>
      </collision>

      <visual name="rl_wheel_visual">
        <geometry>
          <mesh>
            <uri>model://jsc_mecanum_bot_description/meshes/rl_wheel_link.STL</uri>
            <scale>0.5 0.5 0.5</scale>
          </mesh>
          <cylinder>
            <radius>0.04</radius>
            <length>0.035</length>
          </cylinder>
        </geometry>
        <material> 
          <ambient>0.1 0.1 0.1 1</ambient>
          <diffuse>0.1 0.1 0.1 1</diffuse>
          <specular>0 0 0 0</specular>
          <emissive>0 0 0 1</emissive>
        </material>
      </visual>
    </link>

    <link name="rr_wheel_link">
      <pose>-0.063 -0.04750 0 0 0 -1.570796327</pose>
      <inertial>
        <mass>0.2</mass>
        <inertia>
          <ixx>0.01</ixx> <iyy>0.01</iyy> <izz>0.01</izz>
        </inertia>
      </inertial>
      <collision name="rr_wheel_collision">
        <geometry>
          <cylinder>
            <radius>0.04</radius>
            <length>0.035</length>
          </cylinder>
        </geometry>
      </collision>

      <visual name="rr_wheel_visual">
        <geometry>
          <mesh>
            <uri>model://jsc_mecanum_bot_description/meshes/fr_wheel_link.STL</uri>
            <scale>0.5 0.5 0.5</scale>
          </mesh>
          <cylinder>
            <radius>0.04</radius>
            <length>0.035</length>
          </cylinder>
        </geometry>
        <material> 
          <ambient>0.1 0.1 0.1 1</ambient>
          <diffuse>0.1 0.1 0.1 1</diffuse>
          <specular>0 0 0 0</specular>
          <emissive>0 0 0 1</emissive>
        </material>
      </visual>
    </link>

    <link name="lidar_link">
      <pose>0.05 0 0.085 0 0 0</pose>
      <inertial>
        <mass>0.1</mass>
        <inertia>
          <ixx>0.01</ixx> <iyy>0.01</iyy> <izz>0.01</izz>
        </inertia>
      </inertial>
      <collision name="lidar_collision">
        <geometry>
          <cylinder>
            <radius>0.02</radius>
            <length>0.01</length>
          </cylinder>
        </geometry>
      </collision>

      <visual name="lidar_visual">
        <geometry>
          <cylinder>
            <radius>0.02</radius>
            <length>0.01</length>
          </cylinder>
        </geometry>
        <material>
          <ambient>0.8 0.8 0.8 1</ambient>
          <diffuse>0.8 0.8 0.8 1</diffuse>
          <specular>0 0 0 0</specular>
          <emissive>0 0 0 1</emissive>
        </material>
      </visual>

      <sensor name="lidar" type="ray">
        <always_on>true</always_on>
        <visualize>true</visualize>
        <update_rate>3200</update_rate>
        <ray>
          <scan>
            <horizontal>
              <samples>360</samples>
              <resolution>1.00000</resolution>
              <min_angle>0.000000</min_angle>
              <max_angle>6.280000</max_angle>
            </horizontal>
          </scan>
          <range>
            <min>0.060000</min>
            <max>30</max>
            <resolution>0.015000</resolution>
          </range>
          <noise>
            <type>gaussian</type>
            <mean>0.0</mean>
            <stddev>0.01</stddev>
          </noise>
        </ray>
        <plugin name="scan" filename="libgazebo_ros_ray_sensor.so">
          <ros>
            <remapping>~/out:=scan</remapping>
          </ros>
          <output_type>sensor_msgs/LaserScan</output_type>
          <frame_name>laser</frame_name>
        </plugin>
        </sensor>

    </link>

    <!-- *********************** JOINTS ************************************  -->
    <joint name="fl_wheel_joint" type="revolute">
      <parent>base_link</parent>
      <child>fl_wheel_link</child>
      <pose>0 0 0 0 0 0</pose>
      <axis>
        <xyz>1 0 0</xyz>
      </axis>
    </joint>

    <joint name="fr_wheel_joint" type="revolute">
      <parent>base_link</parent>
      <child>fr_wheel_link</child>
      <pose>0 0 0 1.570796327 0 0</pose>
      <axis>
        <xyz>-1 0 0</xyz>
      </axis>
    </joint>

    <joint name="rl_wheel_joint" type="revolute">
      <parent>base_link</parent>
      <child>rl_wheel_link</child>
      <pose>0 0 0 1.570796327 0 0</pose>
      <axis>
        <xyz>1 0 0</xyz>
      </axis>
    </joint>

    <joint name="rr_wheel_joint" type="revolute">
      <parent>base_link</parent>
      <child>rr_wheel_link</child>
      <pose>0 0 0 1.570796327 0 0</pose>
      <axis>
        <xyz>-1 0 0</xyz>
      </axis>
    </joint>

    <joint name="lidar_joint" type="fixed">
      <parent>base_link</parent>
      <child>lidar_link</child>
      <pose>0.05 0 0.085 0 0 0</pose>
    </joint>

<!-- *********************** JOINT STATE PUBLISHER *********************   -->
  
  <plugin name="jsc_mecanum_bot_joint_state" filename="libgazebo_ros_joint_state_publisher.so">
    <ros>
      <remapping>~/out:=joint_states</remapping>
    </ros>
    <update_rate>30</update_rate>

    <joint_name>fl_wheel_joint</joint_name>
    <joint_name>fr_wheel_joint</joint_name>

    <joint_name>rl_wheel_joint</joint_name>
    <joint_name>rr_wheel_joint</joint_name>

  </plugin>


   <!-- *********************** WHEEL ODOMETRY ***************************    -->

   <plugin name="jsc_mobile_bot_diff_drive" filename="libgazebo_ros_diff_drive.so">

    <update_rate>30</update_rate>

    <!-- PRUEBA-->
    <num_wheel_pairs>2</num_wheel_pairs>

    <left_joint>fl_wheel_joint</left_joint>
    <left_joint> rl_wheel_joint</left_joint>

    <right_joint>fr_wheel_joint</right_joint> 
    <right_joint>rr_wheel_joint</right_joint> 


    <!-- kinematics -->
    <wheel_separation>0.19</wheel_separation>
    <wheel_diameter>0.08</wheel_diameter>

    <!-- limits -->
    <max_wheel_torque>2</max_wheel_torque>
    <max_wheel_acceleration>1.0</max_wheel_acceleration>

    <!-- Receive velocity commands on this ROS topic -->
    <command_topic>cmd_vel</command_topic>

    <!-- output -->
    <!-- When false, publish no wheel odometry data to a ROS topic -->
    <publish_odom>true</publish_odom>

    <!-- When true, publish coordinate transform from odom to base_footprint -->
    <!-- I usually use the robot_localization package to publish this transform -->   
    <publish_odom_tf>false</publish_odom_tf>
    
    <!-- When true, publish coordinate transform from base_link to the wheels -->
    <!-- The robot_state_publisher package is often used to publish this transform -->   
    <publish_wheel_tf>false</publish_wheel_tf>

    <odometry_topic>odom</odometry_topic>
    <odometry_frame>odom</odometry_frame>

    <!-- PRUEBA antes era  base_footprint ******************************************-->
    <robot_base_frame>base_link</robot_base_frame>

    <!-- Odometry source, 0 for ENCODER, 1 for WORLD, defaults to WORLD -->
    <odometry_source>0</odometry_source>

    <!-- Change the ROS topic we will publish the odometry data to -->
    <ros>
      <remapping>odom:=wheel/odometry</remapping>
    </ros>

  </plugin>

  </model>
</sdf>